<?xml version="1.0" encoding="UTF-8"?>
<testng-results skipped="0" failed="2" ignored="0" total="5" passed="3">
  <reporter-output>
    <line>
      <![CDATA[Test case tc03 has failed]]>
    </line>
  </reporter-output>
  <suite name="Suite" duration-ms="216738" started-at="2019-09-28T14:07:18Z" finished-at="2019-09-28T14:10:55Z">
    <groups>
    </groups>
    <test name="Test" duration-ms="216738" started-at="2019-09-28T14:07:18Z" finished-at="2019-09-28T14:10:55Z">
      <class name="mainScript.DriverScript">
        <test-method status="FAIL" signature="tc01()[pri:1, instance:mainScript.DriverScript@4b4dd216]" name="tc01" duration-ms="38298" started-at="2019-09-28T15:07:18Z" finished-at="2019-09-28T15:07:57Z">
          <exception class="java.io.FileNotFoundException">
            <message>
              <![CDATA[C:\Users\surai\eclipse-workspace\Selenium Certification Project\SeleniumCertificationData.xlsx (The process cannot access the file because it is being used by another process)]]>
            </message>
            <full-stacktrace>
              <![CDATA[java.io.FileNotFoundException: C:\Users\surai\eclipse-workspace\Selenium Certification Project\SeleniumCertificationData.xlsx (The process cannot access the file because it is being used by another process)
	at java.io.FileOutputStream.open0(Native Method)
	at java.io.FileOutputStream.open(Unknown Source)
	at java.io.FileOutputStream.<init>(Unknown Source)
	at java.io.FileOutputStream.<init>(Unknown Source)
	at utility.ExcelReadWrite.writeValues(ExcelReadWrite.java:67)
	at mainScript.DriverScript.tc01(DriverScript.java:32)
	at sun.reflect.NativeMethodAccessorImpl.invoke0(Native Method)
	at sun.reflect.NativeMethodAccessorImpl.invoke(Unknown Source)
	at sun.reflect.DelegatingMethodAccessorImpl.invoke(Unknown Source)
	at java.lang.reflect.Method.invoke(Unknown Source)
	at org.testng.internal.MethodInvocationHelper.invokeMethod(MethodInvocationHelper.java:108)
	at org.testng.internal.Invoker.invokeMethod(Invoker.java:661)
	at org.testng.internal.Invoker.invokeTestMethod(Invoker.java:869)
	at org.testng.internal.Invoker.invokeTestMethods(Invoker.java:1193)
	at org.testng.internal.TestMethodWorker.invokeTestMethods(TestMethodWorker.java:126)
	at org.testng.internal.TestMethodWorker.run(TestMethodWorker.java:109)
	at org.testng.TestRunner.privateRun(TestRunner.java:744)
	at org.testng.TestRunner.run(TestRunner.java:602)
	at org.testng.SuiteRunner.runTest(SuiteRunner.java:380)
	at org.testng.SuiteRunner.runSequentially(SuiteRunner.java:375)
	at org.testng.SuiteRunner.privateRun(SuiteRunner.java:340)
	at org.testng.SuiteRunner.run(SuiteRunner.java:289)
	at org.testng.SuiteRunnerWorker.runSuite(SuiteRunnerWorker.java:52)
	at org.testng.SuiteRunnerWorker.run(SuiteRunnerWorker.java:86)
	at org.testng.TestNG.runSuitesSequentially(TestNG.java:1301)
	at org.testng.TestNG.runSuitesLocally(TestNG.java:1226)
	at org.testng.TestNG.runSuites(TestNG.java:1144)
	at org.testng.TestNG.run(TestNG.java:1115)
	at org.testng.remote.AbstractRemoteTestNG.run(AbstractRemoteTestNG.java:132)
	at org.testng.remote.RemoteTestNG.initAndRun(RemoteTestNG.java:230)
	at org.testng.remote.RemoteTestNG.main(RemoteTestNG.java:76)
]]>
            </full-stacktrace>
          </exception> <!-- java.io.FileNotFoundException -->
          <reporter-output>
          </reporter-output>
        </test-method> <!-- tc01 -->
        <test-method status="PASS" signature="tc02()[pri:2, instance:mainScript.DriverScript@4b4dd216]" name="tc02" duration-ms="88647" started-at="2019-09-28T15:07:57Z" finished-at="2019-09-28T15:09:25Z">
          <reporter-output>
          </reporter-output>
        </test-method> <!-- tc02 -->
        <test-method status="FAIL" signature="tc03()[pri:3, instance:mainScript.DriverScript@4b4dd216]" name="tc03" duration-ms="41199" started-at="2019-09-28T15:09:25Z" finished-at="2019-09-28T15:10:06Z">
          <exception class="java.lang.AssertionError">
            <message>
              <![CDATA[expected [true] but found [false]]]>
            </message>
            <full-stacktrace>
              <![CDATA[java.lang.AssertionError: expected [true] but found [false]
	at org.testng.Assert.fail(Assert.java:93)
	at org.testng.Assert.failNotEquals(Assert.java:512)
	at org.testng.Assert.assertTrue(Assert.java:41)
	at org.testng.Assert.assertTrue(Assert.java:51)
	at mainScript.DriverScript.tc03(DriverScript.java:69)
	at sun.reflect.NativeMethodAccessorImpl.invoke0(Native Method)
	at sun.reflect.NativeMethodAccessorImpl.invoke(Unknown Source)
	at sun.reflect.DelegatingMethodAccessorImpl.invoke(Unknown Source)
	at java.lang.reflect.Method.invoke(Unknown Source)
	at org.testng.internal.MethodInvocationHelper.invokeMethod(MethodInvocationHelper.java:108)
	at org.testng.internal.Invoker.invokeMethod(Invoker.java:661)
	at org.testng.internal.Invoker.invokeTestMethod(Invoker.java:869)
	at org.testng.internal.Invoker.invokeTestMethods(Invoker.java:1193)
	at org.testng.internal.TestMethodWorker.invokeTestMethods(TestMethodWorker.java:126)
	at org.testng.internal.TestMethodWorker.run(TestMethodWorker.java:109)
	at org.testng.TestRunner.privateRun(TestRunner.java:744)
	at org.testng.TestRunner.run(TestRunner.java:602)
	at org.testng.SuiteRunner.runTest(SuiteRunner.java:380)
	at org.testng.SuiteRunner.runSequentially(SuiteRunner.java:375)
	at org.testng.SuiteRunner.privateRun(SuiteRunner.java:340)
	at org.testng.SuiteRunner.run(SuiteRunner.java:289)
	at org.testng.SuiteRunnerWorker.runSuite(SuiteRunnerWorker.java:52)
	at org.testng.SuiteRunnerWorker.run(SuiteRunnerWorker.java:86)
	at org.testng.TestNG.runSuitesSequentially(TestNG.java:1301)
	at org.testng.TestNG.runSuitesLocally(TestNG.java:1226)
	at org.testng.TestNG.runSuites(TestNG.java:1144)
	at org.testng.TestNG.run(TestNG.java:1115)
	at org.testng.remote.AbstractRemoteTestNG.run(AbstractRemoteTestNG.java:132)
	at org.testng.remote.RemoteTestNG.initAndRun(RemoteTestNG.java:230)
	at org.testng.remote.RemoteTestNG.main(RemoteTestNG.java:76)
]]>
            </full-stacktrace>
          </exception> <!-- java.lang.AssertionError -->
          <reporter-output>
            <line>
              <![CDATA[Test case tc03 has failed]]>
            </line>
          </reporter-output>
        </test-method> <!-- tc03 -->
        <test-method status="PASS" signature="tc04()[pri:4, instance:mainScript.DriverScript@4b4dd216]" name="tc04" duration-ms="47362" started-at="2019-09-28T15:10:06Z" finished-at="2019-09-28T15:10:54Z">
          <reporter-output>
          </reporter-output>
        </test-method> <!-- tc04 -->
        <test-method status="PASS" signature="tc05()[pri:5, instance:mainScript.DriverScript@4b4dd216]" name="tc05" duration-ms="1167" started-at="2019-09-28T15:10:54Z" finished-at="2019-09-28T15:10:55Z">
          <reporter-output>
          </reporter-output>
        </test-method> <!-- tc05 -->
      </class> <!-- mainScript.DriverScript -->
    </test> <!-- Test -->
  </suite> <!-- Suite -->
</testng-results>
